# 8.错误和异常

## 语法错误

```python
>>> while True print('Hello world')
  File "<stdin>", line 1
    while True print('Hello world')
                   ^
SyntaxError: invalid syntax
```

## 异常

>执行时检测到的错误被称为**异常**

```python
>>> 10 * (1/0)
Traceback (most recent call last):
  File "<stdin>", line 1, in <module>
ZeroDivisionError: division by zero
>>> 4 + spam*3
Traceback (most recent call last):
  File "<stdin>", line 1, in <module>
NameError: name 'spam' is not defined
>>> '2' + 2
Traceback (most recent call last):
  File "<stdin>", line 1, in <module>
TypeError: Can't convert 'int' object to str implicitly
```

## 处理异常

- 使用`try ... except`来捕捉和处理异常

    ```python
    >>> try:
    ...     raise Exception('spam', 'eggs')
    ... except Exception as inst:
    ...     print(type(inst))    # the exception instance
    ...     print(inst.args)     # arguments stored in .args
    ...     print(inst)          # __str__ allows args to be printed directly,
    ...                          # but may be overridden in exception subclasses
    ...     x, y = inst.args     # unpack args
    ...     print('x =', x)
    ...     print('y =', y)
    ...
    <class 'Exception'>
    ('spam', 'eggs')
    ('spam', 'eggs')
    x = spam
    y = eggs
    ```

- 有一个可选的 else 子句，在使用时必须放在所有的 except 子句后面。对于在try 子句不引发异常时必须执行的代码来说很有用

    ```python
    for arg in sys.argv[1:]:
        try:
            f = open(arg, 'r')
        except OSError:
            print('cannot open', arg)
        else:
            print(arg, 'has', len(f.readlines()), 'lines')
            f.close()
    ```

## 抛出异常

- 可以通过`raise`语句抛出异常，抛出的可以是异常实例，或者是异常类

    ```python
    >>> try:
    ...     raise NameError('HiThere') #这是抛出一个实例
    ... except NameError:
    ...     print('An exception flew by!')
    ...     raise #重新抛出NameError
    ...
    An exception flew by!
    Traceback (most recent call last):
    File "<stdin>", line 2, in <module>
    NameError: HiThere
    ```

## 用户自定义异常

- 通过直接或间接地从 Exception 类派生，用户可以创建自己的异常类，通过以XXXError命名

    ```python
    class Error(Exception):
        """Base class for exceptions in this module."""
        pass

    class InputError(Error):
        """Exception raised for errors in the input.

        Attributes:
            expression -- input expression in which the error occurred
            message -- explanation of the error
        """

        def __init__(self, expression, message):
            self.expression = expression
            self.message = message

    class TransitionError(Error):
        """Raised when an operation attempts a state transition that's not
        allowed.

        Attributes:
            previous -- state at beginning of transition
            next -- attempted new state
            message -- explanation of why the specific transition is not allowed
        """

        def __init__(self, previous, next, message):
            self.previous = previous
            self.next = next
            self.message = message
    ```

## 定义清理操作

- try语句的另一个可选子句`finally`，用于定义必须在所有情况下执行的清理操作

    ```pythob
    >>> try:
    ...     raise KeyboardInterrupt
    ... finally:
    ...     print('Goodbye, world!')
    ...
    Goodbye, world!
    KeyboardInterrupt
    Traceback (most recent call last):
    File "<stdin>", line 2, in <module>
    ```

- 关于`finally`的一些说明
  - 如果在执行 try 子句期间发生了异常，该异常可由一个 except 子句进行处理。 如果异常没有被 except 子句所处理，则该异常会在 finally 子句执行之后被重新引发。
  - 异常也可能在 except 或 else 子句执行期间发生。 同样地，该异常会在 finally 子句执行之后被重新引发。
  - 如果在执行 try 语句时遇到一个 break, continue 或 return 语句，则 finally 子句将在执行 break, continue 或 return 语句之前被执行。
  - 如果 finally 子句中包含一个 return 语句，则 finally 子句的 return 语句将在执行 try 子句的 return 语句之前取代后者被执行。

## 预定义的清理操作

- `with`语句可以保证资源在使用后被正确地关闭

    ```python
    with open("myfile.txt") as f:
        for line in f:
            print(line, end="")
    ```